INPUTS/draft_input/Linkedin/Comments_75194587.csv
Date,Link,Message
2026-05-23 05:12:48,https://www.linkedin.com/feed/update/urn%3Ali%3Aactivity%3A7459611396499181568,I don’t buy books published after 2023)
2026-05-23 05:11:29,https://www.linkedin.com/feed/update/urn%3Ali%3Aactivity%3A7463197840031457280,Thank you for sharing karuna!
2026-05-16 10:24:10,https://www.linkedin.com/feed/update/urn%3Ali%3Aactivity%3A7461213159836778497,"Sudip, that’s son of a gun will be afraid of writing back from now on"
2026-05-16 05:43:09,https://www.linkedin.com/feed/update/urn%3Ali%3Aactivity%3A7461225090765135872,"Very inspiring post, Jamie, thank you for sharing"
2026-05-15 19:37:41,https://www.linkedin.com/feed/update/urn%3Ali%3Aactivity%3A7460952712973594624,Oleksandr Shelegeda ☝️
2026-05-14 07:19:16,https://www.linkedin.com/feed/update/urn%3Ali%3Aactivity%3A7460573376521154560,Preach brother!
2026-05-12 16:23:15,https://www.linkedin.com/feed/update/urn%3Ali%3AugcPost%3A7459919765768192001,"As a runner, I cannot agree more - never trust a runner!"
2026-05-12 07:27:52,https://www.linkedin.com/feed/update/urn%3Ali%3Aactivity%3A7459823202358444032,This is going to be huge! Looking forward to posts from the event!
2026-05-09 10:30:42,https://www.linkedin.com/feed/update/urn%3Ali%3Aactivity%3A7453044660408573952,"Emma, a while back my ex manager told me that project management is going to disappear as a concept (it is still there though and flourishing). Do you think there will be a massive shift in the change management space as a result of tech shifts we observe now?"
2026-05-08 11:56:22,https://www.linkedin.com/feed/update/urn%3Ali%3Aactivity%3A7458377310430478336,Preach brother!
2026-05-07 19:05:22,https://www.linkedin.com/feed/update/urn%3Ali%3Aactivity%3A7458225155169800192,Wise words
2026-05-06 08:30:48,https://www.linkedin.com/feed/update/urn%3Ali%3Aactivity%3A7457697305593450496,I checked it last week and there are still some users raising questions (technical meaningful questions). I guess the sheer volume is just not the same. Plus all the developers having a grudge on the portal sharing content for training models
2026-05-05 04:28:07,https://www.linkedin.com/feed/update/urn%3Ali%3Aactivity%3A7455632124809834496,Preach brother!
2026-04-25 08:53:09,https://www.linkedin.com/feed/update/urn%3Ali%3Aactivity%3A7449776991014326273,"Neale, for a brief second I thought it was you 😅"
2026-04-17 13:37:14,https://www.linkedin.com/feed/update/urn%3Ali%3Aactivity%3A7450899596538593280,"Louis - keep going, don't stop!"
2026-04-17 08:49:06,https://www.linkedin.com/feed/update/urn%3Ali%3Aactivity%3A7450786043798163458,They don’t know who they are messing with! 🫡
2026-04-16 15:34:49,https://www.linkedin.com/feed/update/urn%3Ali%3Aactivity%3A7450518914284892160,"Aarti, good thing Konan doesn’t know how to use it so polar bears are safe! 😅"
2026-04-13 09:29:00,https://www.linkedin.com/feed/update/urn%3Ali%3Aactivity%3A7449358295343140864,""
2026-04-09 07:03:37,https://www.linkedin.com/feed/update/urn%3Ali%3Aactivity%3A7447360041055125504,"Simon, we are expecting delivery of his backup in a month :)"
2026-04-08 10:03:26,https://www.linkedin.com/feed/update/urn%3Ali%3Aactivity%3A7447360041055125504,"Oleksandr, he already starts to look for shortcuts ))"
2026-04-08 10:01:03,https://www.linkedin.com/feed/update/urn%3Ali%3Aactivity%3A7447360041055125504,"Donna, reading is already added for this sprint 😅 but playing will add next wek"
2026-03-15 10:37:34,https://www.linkedin.com/feed/update/urn%3Ali%3Aactivity%3A7438796368564932608,"When I lived in China, I paid 700 yuan for an annual gym membership (or about 8 bucks per month). Just to say that I recognise some of the numbers but some make no sense."
2026-03-13 16:16:29,https://www.linkedin.com/feed/update/urn%3Ali%3Aactivity%3A7438229359498375171,Bravo Thiago!
2026-03-12 08:23:12,https://www.linkedin.com/feed/update/urn%3Ali%3AugcPost%3A7437186390347530242,"That is a massive accomplishment! Well done, Alex and keep us posted on practical application of your knew knowledge and skills!"
2026-03-03 11:26:37,https://www.linkedin.com/feed/update/urn%3Ali%3AugcPost%3A7434553013375012864,Change is indeed hard to digest
2026-02-27 09:24:58,https://www.linkedin.com/feed/update/urn%3Ali%3Aactivity%3A7432903381603672065,New season of Simpsons
2026-02-26 18:31:41,https://www.linkedin.com/feed/update/urn%3Ali%3Aactivity%3A7432837677965611008,So what is it going to be?)
2026-02-26 18:29:18,https://www.linkedin.com/feed/update/urn%3Ali%3Aactivity%3A7432800291303030785,What a sweet post! Congratulations!
2026-02-24 19:32:12,https://www.linkedin.com/feed/update/urn%3Ali%3Aactivity%3A7386421114521927681,I finally finished it!
2026-02-24 19:31:23,https://www.linkedin.com/feed/update/urn%3Ali%3Aactivity%3A7421288582058807296,"Thank you, Glyn! It’s important to know what people who have a clue about a subject think about it."
2026-02-24 19:28:34,https://www.linkedin.com/feed/update/urn%3Ali%3Aactivity%3A7432111776894447617,"So happy for you, Emma!"
2026-02-21 20:15:20,https://www.linkedin.com/feed/update/urn%3Ali%3Aactivity%3A7430994375435812864,"Jyothi, thank you for your willingness to share the wisdom 🤜🤛"
2026-02-17 21:19:47,https://www.linkedin.com/feed/update/urn%3Ali%3AugcPost%3A7425513796074463232,You will find company appreciating your skills real soon! 🤜🤛
2026-02-17 21:18:05,https://www.linkedin.com/feed/update/urn%3Ali%3Aactivity%3A7429510704086282240,Thank you for the post. A gem 💎
2026-02-17 11:51:58,https://www.linkedin.com/feed/update/urn%3Ali%3Aactivity%3A7429466671498657793,That is a nice one!
2026-02-13 14:23:47,https://www.linkedin.com/feed/update/urn%3Ali%3AugcPost%3A7427757244298977281,"That’s a massive, without overstatement, accomplishment! Kudos 🤜🤛"
2026-02-13 14:18:03,https://www.linkedin.com/feed/update/urn%3Ali%3Aactivity%3A7428010036175659008,Дякую за список «прапорів»!
2026-02-12 06:59:28,https://www.linkedin.com/feed/update/urn%3Ali%3Aactivity%3A7427245036259557376,Oleksandr Shelegeda I was actually thinking of leveraging this trick myself
2026-02-11 15:38:30,https://www.linkedin.com/feed/update/urn%3Ali%3Aactivity%3A7427329243711430658,I am actually in progress of doing Your course on orchestration!)
2026-02-09 15:35:10,https://www.linkedin.com/feed/update/urn%3Ali%3Aactivity%3A7422537504140070912,"BL being SME sounds very Japanese, which is very different from European cultures though still not uncommon."
2026-02-07 09:56:22,https://www.linkedin.com/feed/update/urn%3Ali%3Aactivity%3A7423097824025808896,"That’s a big thing, Kuba, impressive accomplishment! 🇫🇷"
2026-02-02 14:02:44,https://www.linkedin.com/feed/update/urn%3Ali%3AugcPost%3A7424080468586889217,这是好消息。
2026-01-30 20:30:14,https://www.linkedin.com/feed/update/urn%3Ali%3AugcPost%3A7423096000027910145,Looking forward to hearing your experience as a manager!
2026-01-25 13:01:07,https://www.linkedin.com/feed/update/urn%3Ali%3Aactivity%3A7420088346175057922,"For such a “noble” cause, it would be a sin not to “defrost” the funds)"
2026-01-24 13:31:31,https://www.linkedin.com/feed/update/urn%3Ali%3Aactivity%3A7420600483070877696,Why does he have the same footprints like penguin 🐧?
2026-01-22 11:17:57,https://www.linkedin.com/feed/update/urn%3Ali%3Aactivity%3A7419829576035467265,Very accurate
2026-01-18 20:06:19,https://www.linkedin.com/feed/update/urn%3Ali%3Aactivity%3A7418650067705749504,"Sorry about that, Alena)"
2026-01-16 14:46:34,https://www.linkedin.com/feed/update/urn%3Ali%3AugcPost%3A7417524840305360896,"Ооо, дякую, дякую! 🤜🤛"
2026-01-15 19:36:08,https://www.linkedin.com/feed/update/urn%3Ali%3Aactivity%3A7417335019452436480,Are there any guidance for the funding source depending on nature of business?
2026-01-15 16:37:26,https://www.linkedin.com/feed/update/urn%3Ali%3Aactivity%3A7417325872300335105,"My wife asked me yesterday “why in Central Europe flor count starts with zero and in Eastern it starts with one?”, I could only guess that folks in CE have more programmer mindset 🤪"
2026-01-11 18:56:32,https://www.linkedin.com/feed/update/urn%3Ali%3Aactivity%3A7416171247669088257,It’s so closely describes what me and my family goes through. I hope you will make it through with as little damage as possible.
